# defer 语句

参考：[Golang 之轻松化解 defer 的温柔陷阱](https://mp.weixin.qq.com/s?__biz=MjM5MDUwNTQwMQ==&mid=2257483686&idx=1&sn=9be2edd3e5cb8202dd34fbd5309c7a50&scene=19#wechat_redirect)

## 基础使用

`defer` 确保**调用在函数结束时（无论是否发生 `return` 或异常）发生**！！

- 多个 defer 语句时，在函数 return 前，采用 LIFO(先进后出)的执行顺序
  - 原因：后定义的函数可能会依赖前面的资源，要先执行；否则，如果前面先执行，那后面函数的依赖就没有了

```go
// 输出结果为：2  1 panic: error occurred
func TestDeferStack(t *testing.T) {
	defer t.Log(1)
	defer t.Log(2)
	panic("error occurred")
	t.Log(3)
}
```

---

- defer 函数定义时对外部变量的引用有两种方式：
  - 外部变量作为函数参数，在 defer 语句定义时外部变量会被缓存起来
  - 外部变量作为闭包引用，在 defer 函数真正调用时根据整个上下文确定当前的值。

```go
type number int

func (n number) print() {
	fmt.Println(n)
}

func (n *number) pprint() {
	fmt.Println(*n)
}

func main() { // 输出：3 3 3 0
	var n number
  // n 是值，此时 n == 0
	defer n.print()   // 0
  // n 是引用，最终 n == 3
	defer n.pprint()  // 3
  // 闭包，引用外部函数 n，真正调用时根据上下文确定 n 的值
	defer func() {
		n.print()     // 3
	}()
	defer func() {
		n.pprint()    // 3
	}()
	n = 3
}
```

---

使用 defer：

```go
file, err := os.Open("file")
// 注意，先判断 err 再用 defer 关闭文件
if err != nil{
	return
}
// 先判断 file 是否为空，否则会 panic
if file != nil{
  // defer 函数定义时，参数已经复制进去了，
  // 即使再打开第二个文件(也使用 file 变量)，之后真正执行 Close() 时
  // 关闭的也还是是正确的 file
  defer func(f io.Closer) {
    if err := f.Close(); err != nil {
      fmt.Printf("defer close file err %v\n",err)
    }
  }(file)
}
```

## 遇到 return

defer 语句在和 return 语句同时出现时，在编译后就会变成：

1. 返回值 = xxx
2. 调用 defer 函数
3. 空的 return

```go
// 三步拆解：
//  1. r = n + 1 = 4
//  2. 执行第二个 defer，但此时 f() 未定义，故引发异常
//  	 执行第一个 defer，r = r + n = 7，recover 异常，程序正常执行
//  3. return
// 注意：如果没有 recover() 程序会产生 panic，f(3) 报错无法返回值，程序只输出报错信息
func TestDeferWithPanic(t *testing.T) {
	t.Log(f_for_defer(3))
}

func f_for_defer(n int) (r int) {
	defer func() {
		r += n
		recover()
	}()
	var f func()
	defer f()
	f = func() {
		r += 2
	}
	return n + 1
}
```

## 参数(含接收者)

defer 函数的参数（包括接收者）是在 defer 语句出现的位置做计算的，而不是在函数执行的时候计算的!

- 参数

```go
func TestArgumentOfDeferFunc(t *testing.T) {
	calc := func(index string, a, b int) int {
		ret := a + b
		println(index, a, b, ret)
		return ret
	}
	a := 1
  b := 2
  // 这里会先计算 calc("10", a, b)
	defer calc("1", a, calc("10", a, b))
	a = 0
	defer calc("2", a, calc("20", a, b))
	b = 1
}
输出为：
10 1 2 3
20 0 2 2
2 0 2 2
1 1 3 4
```

- 接收者

```go
type slice []int

func (s *slice) Add(elem int) *slice {
	*s = append(*s, elem)
	fmt.Print(elem)
	return s
}

func NewSlice() slice{
	return make(slice,0)  // 注意这里可以使用 make 来创建 []int 重定义后的类型
}
// 输出 132
func TestArgument_receiver(t *testing.T) {
	s := NewSlice()
	// s.Add(1) 会先于 s.Add(3) 执行
	defer s.Add(1).Add(2)
	s.Add(3)
}
```

## 注意

`os.Exit()` 调用后，defer 语句调用将不会被执行！

使用时注意 `log.Fatal()` 会调用 `os.Exit()`！

```go
func main(){
  defer println("bye") // 不会打印出来
  os.Exit(1)
}
```

`runtime.Goexit()` 调用后，defer 语句调用会被执行。

```go
func main(){
  c := make(chan int)
  go func(){
    defer close(c)
    defer println("bye") // 会打印出来
    runtime.Goexit()
  }()
  <-c
}
```

# 错误处理

在处理一个 panic 异常时，Go 的 runtime 会打开函数堆栈，直到 panic 异常恢复为止。如果当 runtime 到达了一个函数堆栈的顶部时，panic 异常恢复函数仍没有被调用，那么意味着程序“死亡”了。

**goroutine 上的 panic 异常不能跳转到启动 goroutine 的函数的调用堆栈上！！！**

## error

`error` 是一个接口类型，且只含有一个 `Error() string` 方法。

- 定义一个 `error`

```go
//方法一
err := errors.New("text")
//方法二：实现 Error() string 方法
```

- `error` 类型的值，其字符串表示形式取决于其 `Error()` 方法！等价于其他类型的 `String()` 方法。

## 错误判断

怎样判断一个错误值具体代表哪一类错误？

1. 对于类型在已知范围内的一系列错误值，一般使用类型断言表达式或类型 switch 语句判断；
2. 对于已有相应变量且类型相同的一系列错误值，一般直接使用判等操作判断；
3. 对于没有响应变量且类型位置的一系列错误值，只能用错误信息的字符串表示来判断。

类型在已知范围内的错误值举例：`os.PathError`、`os.LinkError`、`os.SyscallError`、`os/exec.Error`，这些错误的**指针类型**都是 `error` 接口的实现类型，同时还包含了一个名为 Err、类型为 `error` 接口类型的代表潜在错误的字段。

- 类型断言表达式

```go
//获取和返回已知的操作系统相关错误的潜在错误值
func underlyingError(err error) error {
	switch err := err.(type) {
	case *os.PathError:
		return err.Err
	case *os.LinkError:
		return err.Err
	case *os.SyscallError:
		return err.Err
	case *exec.Error:
		return err.Err
	}
	return err
}
```

错误类型不同时，可以像上面那样分辨，但是错误值类型相同时，就不能了。如：`os.ErrInvalid`、`os.ErrPermission`、`os.ErrExist` 等这些错误值都是通过调用 `errors.New()` 初始化的，这些事已经定义好的、确切的错误值，os 包中的代码有时会把它们当作潜在错误值封装进前面的错误类型的值中。此时可以使用 switch 语句判断：

- 类型 switch 语句

```go
printError := func(i int, err error) {
	if err == nil {
		fmt.Println("nil error")
		return
	}
	err = underlyingError(err) //获得潜在错误值
	switch err {
	case os.ErrClosed:
		fmt.Printf("error(closed)[%d]: %s\n", i, err)
	case os.ErrInvalid:
		fmt.Printf("error(invalid)[%d]: %s\n", i, err)
	case os.ErrPermission:
		fmt.Printf("error(permission)[%d]: %s\n", i, err)
	}
}
```

## recover()

`panic()`：用于不可恢复的错误停止当前函数执行；一直向上传递，执行每一层的 defer 语句。如果碰到 `recover()` 就会把 `panic` 结束，如果没有遇见`recover()`，程序退出。

`recover()`：把 `panic` 状态取消 ，让程序正常运行；可以获取`panic`的值。只在 defer 的上下文中才有效(且只有通过在 defer 中用匿名函数调用才有效)，直接调用的话，只会返回 `nil`。

`recover()` 必须隔一个函数栈才能捕获到异常！所以需要在 defer 函数中直接调用才有效！！如下：

```go
func main() {
	// defer recover()   defer直接调用recover()是无效的！
	// recover()       是无效的
	// 以下是无效的
	// defer func(){
	// 	defer func(){
	// 		recover()
	// 	}
	// }
	// 有效的
	defer func() {
			recover()
	}()
	panic(1)
}
```

在 Go 中，因 panic 导致程序结束运行的退出状态码一般都会是 2。

注意多层函数调用过程中 `panic` 的传递和中途 `recover` 的恢复！！！

```go
func use1() {
	fmt.Println("use 1 before")
	use2()
	fmt.Println("use 1 after")
}

func use2() {
	defer func() {
		fmt.Println(recover())  //会返回 panic() 参数中传入的错误！
	}()
	fmt.Println("use 2 before")
	use3()
	fmt.Println("use 2 after")
}

func use3() {
	fmt.Println("use 3 before")
	panic("出错啦。。。。")
	fmt.Println("use 3 after")
}

func TestPanic(t *testing.T) {
	use1()
}
```

输出：

```go
use 1 before
use 2 before
use 3 before
出错啦。。。。
use 1 after
```

Go 语言运行时系统自行抛出的 panic 都属于致命错误，都是无法恢复的，调用 `recover()` 函数对它们不起作用！！！
